HEY! QA here! getting errors in browser:

2025-01-06 01:51:06,774 - werkzeug - INFO - 127.0.0.1 - - [06/Jan/2025 01:51:06] "GET / HTTP/1.1" 500 -
Traceback (most recent call last):
  File "C:\github\SF4\.venv\lib\site-packages\flask\app.py", line 2213, in __call__
    return self.wsgi_app(environ, start_response)
  File "C:\github\SF4\.venv\lib\site-packages\flask\app.py", line 2193, in wsgi_app
    response = self.handle_exception(e)
  File "C:\github\SF4\.venv\lib\site-packages\flask\app.py", line 2190, in wsgi_app
    response = self.full_dispatch_request()
  File "C:\github\SF4\.venv\lib\site-packages\flask\app.py", line 1486, in full_dispatch_request
    rv = self.handle_user_exception(e)
  File "C:\github\SF4\.venv\lib\site-packages\flask\app.py", line 1484, in full_dispatch_request
    rv = self.dispatch_request()
  File "C:\github\SF4\.venv\lib\site-packages\flask\app.py", line 1469, in dispatch_request
    return self.ensure_sync(self.view_functions[rule.endpoint])(**view_args)
  File "C:\github\SF4\app\routes\public_routes.py", line 71, in index
    tags = Tag.query.order_by(Tag.name).all()
  File "C:\github\SF4\.venv\lib\site-packages\flask_sqlalchemy\model.py", line 22, in __get__
    return cls.query_class(
  File "C:\github\SF4\.venv\lib\site-packages\sqlalchemy\orm\query.py", line 276, in __init__
    self._set_entities(entities)
  File "C:\github\SF4\.venv\lib\site-packages\sqlalchemy\orm\query.py", line 288, in _set_entities
    self._raw_columns = [
  File "C:\github\SF4\.venv\lib\site-packages\sqlalchemy\orm\query.py", line 289, in <listcomp>
    coercions.expect(
  File "C:\github\SF4\.venv\lib\site-packages\sqlalchemy\sql\coercions.py", line 406, in expect
    insp._post_inspect
  File "C:\github\SF4\.venv\lib\site-packages\sqlalchemy\util\langhelpers.py", line 1260, in __get__
    obj.__dict__[self.__name__] = result = self.fget(obj)
  File "C:\github\SF4\.venv\lib\site-packages\sqlalchemy\orm\mapper.py", line 2707, in _post_inspect
    self._check_configure()
  File "C:\github\SF4\.venv\lib\site-packages\sqlalchemy\orm\mapper.py", line 2386, in _check_configure      
    _configure_registries({self.registry}, cascade=True)
  File "C:\github\SF4\.venv\lib\site-packages\sqlalchemy\orm\mapper.py", line 4199, in _configure_registries 
    _do_configure_registries(registries, cascade)
  File "C:\github\SF4\.venv\lib\site-packages\sqlalchemy\orm\mapper.py", line 4236, in _do_configure_registries
    raise e
sqlalchemy.exc.InvalidRequestError: One or more mappers failed to initialize - can't proceed with initialization of other mappers. Triggering mapper: 'Mapper[Stipend(stipend)]'. Original exception was: Mapper 'Mapper[Tag(tag)]' has no property 'stipends'.  If this property was indicated from other mappers or configure events, ensure registry.configure() has been called.